File: ТВЕРДОТЕЛЬНАЯ СВЧ-ЭЛЕКТРОНИКА/98.txt
МОДИФИЦИРОВАНИЕ НАНОПОРОШКОВ CU И W
КОРОТКОИМПУЛЬСНЫМ СВЧ-ИЗЛУЧЕНИЕМ

А.В. Мостовщиков1,2, А.П. Ильин1, П.Ю. Чумерин1
1 Томский политехнический университет
2 Томский государственный университет систем управления и радиоэлектроники
E-mail: avmost@tpu.ru

В работе исследовано влияние короткоимпульсного СВЧ-излучения с длиной им-
пульса 25 нс, плотностью мощности 8 кВт/см2 на термохимические свойства нанопорош-
ков вольфрама и меди. Установлено, что после действия излучения порошки практически
не содержат сорбированной воды. Обнаруженный эффект может быть использован в ад-
дитивных технологиях.
Ключевые слова: СВЧ-излучения, нанопорошки металлов, вольфрам, медь, де-
сорбция.

Нанопорошки металлов находят применение в процессах химического
катализа, синтеза, при производстве керамик, пиротехнических смесей и т.п.
Актуальной задачей является модифицирование физико-химических пара-
метров порошков для придания им определённых свойств. В настоящее вре-
мя проблемы модифицирования решаются с помощью химической обработки
порошков, механоактивации. Вместе с тем, классические методы имеют ряд
недостатков, таких как загрязнение исходных порошков примесями других
элементов (соединений).
Новым, активно развивающимся направлением модифицирования по-
рошков является применение внешнего высокоэнергетического воздействия
[1]. В частности, известно, что воздействие электронных пучков на порошки
металлов, увеличивает их тепловой эффект окисления, снижает температуру
начала окисления. Известно, что действие СВЧ-излучения с частотой 9,4 ГГц
и длиной импульса 3 мкс изменяет физико-химические свойства нано- и
микронных порошков алюминия и железа [2].


169
Для проведения экспериментов по изучению действия СВЧ-излучения
S-диапазона на физико-химические свойства электровзрывных нанопорош-
ков меди (рис. 1 а) и вольфрама (рис. 1 б) [3] было использовано излучение
частотой 2,85 ГГц, длина импульса составляла 25 нс, частота следования им-
пульсов 25 Гц, время облучения 1 минута. Среднеповерхностный диаметр
частиц нанопорошка меди составлял 70 нм, а нанопорошка вольфрама 200
нм. Схема экспериментального стенда и характеристики применяемого обо-
рудования представлены в работе [2].



а





б

Рисунок 1. Микрофотографии электровзрывных нанопорошков меди (а) и вольфрама (б)

После облучения образцы исследовали с помощью метода дифферен-
циального термического анализа [4], как позволяющего наиболее полно ис-
следовать изменение термохимических параметров порошков после облуче-
ния. Термограммы образцов меди после СВЧ-облучения представлены на ри-
сунке 2.

Residue:
8.980mg
(130.5%)
208.4°C
178.3°C
1661J/g
178.7°C
2.926°C·min/mg
1036.2°C
1026.2°C
587.9J/g
0.01961mg
0.6549mg
0.9902mg
0.4695mg
324.3°C
-0.5
0.0
0.5
1.0
Temperature Difference (°C/mg)
-20
-15
-10
-5
0
5
Heat Flow (W/g)
6.75
7.25
7.75
8.25
8.75
Weight (mg)
0
200
400
600
800
1000
1200
Temperature (°C)
Instrument: SDT Q600 V20.9 Build 20
Exo Up

241.2°C
185.1°C
1520J/g
186.4°C
1.858°C·min/mg
320.2°C
0.3784mg
0.5637mg
0.07864mg
Residue:
6.549mg
(118.6%)
Residue:
6.109mg
(110.6%)
1038.5°C
1029.8°C
452.5J/g
1125.3°C
1119.2°C
146.6J/g
1029.8°C
0.721°C·min/mg
-1.0
-0.8
-0.6
-0.4
-0.2
0.0
0.2
Temperature Difference (°C/mg)
-30
-20
-10
0
10
Heat Flow (W/g)
5.4
5.6
5.8
6.0
6.2
6.4
6.6
6.8
Weight (mg)
0
200
400
600
800
1000
1200
Temperature (°C)
Q
Exo Up

а






б

Рисунок 2. Термограммы нанопорошка меди до (а) и после СВЧ-облучения

Согласно данным термического анализа, тепловой эффект окисления
снизился незначительно (на ~ 5,3 %). Учитывая, что погрешность измерения
величины удельного теплового эффекта составляла ± 1,8 %, можно сделать


170
вывод, что СВЧ-излучение практически не изменяет тепловой эффект окис-
ления, снижая содержание сорбированных газов практически до 0 % (ниже
порога чувствительности прибора: менее ~ 10–4 грамма).
Термограммы образцов вольфрама после СВЧ-облучения представлены
на рисунке 3. Удельный тепловой эффект окисления возрос на 16,5 %, со-
держание сорбированных газов уменьшилось почти до 0 %.

112.4°C
99.7°C
66.61J/g
100.1°C
0.100°C·min/mg
0.2246mg
0.07201mg
0.2667mg
1.400mg
554.8°C
453.0°C
3229J/g
454.8°C
2.133°C·min/mg
541.9°C
412.7°C
112.1°C
0.1397mg
0.1877mg
Residue:
8.684mg
(124.3%)
1099.2°C
1133.3°C
-0.6
-0.4
-0.2
0.0
0.2
0.4
0.6
Temperature Difference (°C/mg)
-15
-10
-5
0
5
Heat Flow (W/g)
6.5
7.0
7.5
8.0
8.5
9.0
Weight (mg)
0
200
400
600
800
1000
1200
Temperature (°C)
Instrument: SDT Q600 V20.9 Build 20
Exo Up

Residue:
10.65mg
(124.0%)
2.078mg
625.3°C
510.6°C
3764J/g
517.6°C
2.197°C·min/mg
914.0°C
971.2°C
1174.2°C
381.5°C
-0.2
-0.1
0.0
0.1
Temperature Difference (°C/mg)
-12
-10
-8
-6
-4
-2
0
2
Heat Flow (W/g)
8.5
9.0
9.5
10.0
10.5
11.0
Weight (mg)
0
200
400
600
800
1000
1200
Temperature (°C)
Exo Up

a






б

Рисунок 3. Термограммы нанопорошка вольфрама до (а) и после СВЧ-облучения

Общей
закономерностью
действия
короткоимпульсного
СВЧ-
излучения (25 нс, 2,85 ГГц) на нанопорошки вольфрама и меди является
снижение количества сорбированных поверхностью наночастиц газов и мо-
лекул воды. Это может быть использовано для подготовки поверхности по-
рошков при их использовании в аддитивных технологиях для улучшения ка-
чества поверхности порошка-сырья. Учитывая, что длительность СВЧ-
импульса недостаточна для теплового нагрева порошка, процесс десорбции
воды протекает по нетепловому механизму.
Работа выполнена при финансовой поддержке Министерства науки и
высшего образования РФ (государственное задание № 11.1928.2017/4.6).

Библиографический список

1. Андриевский Р.А. Наноструктуры в экстремальных условиях // Успехи физических
наук, 2014, Т. 184, №10, С. 1017–1032.
2. Мостовщиков А.В., Ильин А.П., Чумерин П.Ю. и др. Влияние СВЧ-излучения на тер-
мическую стабильность нанопорошка алюминия // Письма в ЖТФ, 2016, Т. 42, №7, C. 17–
22.
3. Zarko V.E., Gromov A.A. Energetic nanomaterials: Synthesis, characterization, and applica-
tion // Wiley-VCH, Weinheim, 2016, 374 p.
4. Уэндландт У. Термические методы анализа // М.: Мир, 1978, 527 с.




171